[2025-08-27 14:25:15,317] CRITICAL django.request: Platform is running at risk
[2025-08-27 14:25:15,317] INFO django.request: MyView GET called by user AnonymousUser
[2025-08-27 14:30:12,298] CRITICAL django.request: Platform is running at risk
[2025-08-27 14:30:12,298] INFO django.request: MyView GET called by user AnonymousUser
[2025-08-27 14:30:12,324] ERROR django.request: Internal Server Error: /
Traceback (most recent call last):
  File "/Users/modarwish/Documents/Learn/backend/djangoapp/demoapp/path/to/venv/lib/python3.13/site-packages/django/core/handlers/exception.py", line 55, in inner
    response = get_response(request)
  File "/Users/modarwish/Documents/Learn/backend/djangoapp/demoapp/path/to/venv/lib/python3.13/site-packages/django/core/handlers/base.py", line 197, in _get_response
    response = wrapped_callback(request, *callback_args, **callback_kwargs)
  File "/Users/modarwish/Documents/Learn/backend/djangoapp/demoapp/path/to/venv/lib/python3.13/site-packages/django/views/decorators/csrf.py", line 56, in wrapper_view
    return view_func(*args, **kwargs)
  File "/Users/modarwish/Documents/Learn/backend/djangoapp/demoapp/path/to/venv/lib/python3.13/site-packages/django/views/generic/base.py", line 104, in view
    return self.dispatch(request, *args, **kwargs)
           ~~~~~~~~~~~~~^^^^^^^^^^^^^^^^^^^^^^^^^^
  File "/Users/modarwish/Documents/Learn/backend/djangoapp/demoapp/path/to/venv/lib/python3.13/site-packages/rest_framework/views.py", line 517, in dispatch
    self.response = self.finalize_response(request, response, *args, **kwargs)
                    ~~~~~~~~~~~~~~~~~~~~~~^^^^^^^^^^^^^^^^^^^^^^^^^^^^^^^^^^^^
  File "/Users/modarwish/Documents/Learn/backend/djangoapp/demoapp/path/to/venv/lib/python3.13/site-packages/rest_framework/views.py", line 429, in finalize_response
    assert isinstance(response, HttpResponseBase), (
           ~~~~~~~~~~^^^^^^^^^^^^^^^^^^^^^^^^^^^^
AssertionError: Expected a `Response`, `HttpResponse` or `StreamingHttpResponse` to be returned from the view, but received a `<class 'NoneType'>`
[2025-08-27 14:38:05,979] CRITICAL django.request: Platform is running at risk
[2025-08-27 14:38:05,979] INFO django.request: MyView GET called by user AnonymousUser
[2025-08-27 14:38:05,995] WARNING django.request: Bad Request: /
[2025-08-28 06:34:06,180] CRITICAL django.request: Platform is running at risk
[2025-08-28 06:34:06,181] INFO django.request: MyView GET called by user AnonymousUser
[2025-08-28 06:34:06,192] WARNING django.request: Bad Request: /
[2025-08-28 06:34:06,286] WARNING django.request: Not Found: /favicon.ico
[2025-08-28 06:38:57,933] WARNING django.request: Not Found: /api/v1/
[2025-08-28 06:39:11,273] WARNING django.request: Method Not Allowed: /api/v1/auth/jwt/register/
[2025-08-28 06:43:25,079] WARNING django.request: Method Not Allowed: /api/v1/auth/jwt/register/
[2025-08-28 06:43:26,618] WARNING django.request: Method Not Allowed: /api/v1/auth/jwt/register/
[2025-08-28 06:43:45,578] WARNING django.request: Bad Request: /api/v1/auth/jwt/register/
[2025-08-28 06:45:31,548] WARNING django.request: Bad Request: /api/v1/auth/jwt/register/
[2025-08-28 06:46:15,909] WARNING django.request: Method Not Allowed: /api/v1/auth/jwt/register/
[2025-08-28 13:35:46,012] WARNING django.request: Bad Request: /
[2025-08-28 13:35:46,068] WARNING django.request: Bad Request: /favicon.ico
[2025-08-28 13:36:08,845] CRITICAL django.request: Platform is running at risk
[2025-08-28 13:36:08,845] INFO django.request: MyView GET called by user AnonymousUser
[2025-08-28 13:36:08,863] WARNING django.request: Bad Request: /
[2025-08-28 13:36:08,967] WARNING django.request: Not Found: /favicon.ico
