[2025-08-27 14:25:15,317] CRITICAL django.request: Platform is running at risk
[2025-08-27 14:25:15,317] INFO django.request: MyView GET called by user AnonymousUser
[2025-08-27 14:30:12,298] CRITICAL django.request: Platform is running at risk
[2025-08-27 14:30:12,298] INFO django.request: MyView GET called by user AnonymousUser
[2025-08-27 14:30:12,324] ERROR django.request: Internal Server Error: /
Traceback (most recent call last):
  File "/Users/modarwish/Documents/Learn/backend/djangoapp/demoapp/path/to/venv/lib/python3.13/site-packages/django/core/handlers/exception.py", line 55, in inner
    response = get_response(request)
  File "/Users/modarwish/Documents/Learn/backend/djangoapp/demoapp/path/to/venv/lib/python3.13/site-packages/django/core/handlers/base.py", line 197, in _get_response
    response = wrapped_callback(request, *callback_args, **callback_kwargs)
  File "/Users/modarwish/Documents/Learn/backend/djangoapp/demoapp/path/to/venv/lib/python3.13/site-packages/django/views/decorators/csrf.py", line 56, in wrapper_view
    return view_func(*args, **kwargs)
  File "/Users/modarwish/Documents/Learn/backend/djangoapp/demoapp/path/to/venv/lib/python3.13/site-packages/django/views/generic/base.py", line 104, in view
    return self.dispatch(request, *args, **kwargs)
           ~~~~~~~~~~~~~^^^^^^^^^^^^^^^^^^^^^^^^^^
  File "/Users/modarwish/Documents/Learn/backend/djangoapp/demoapp/path/to/venv/lib/python3.13/site-packages/rest_framework/views.py", line 517, in dispatch
    self.response = self.finalize_response(request, response, *args, **kwargs)
                    ~~~~~~~~~~~~~~~~~~~~~~^^^^^^^^^^^^^^^^^^^^^^^^^^^^^^^^^^^^
  File "/Users/modarwish/Documents/Learn/backend/djangoapp/demoapp/path/to/venv/lib/python3.13/site-packages/rest_framework/views.py", line 429, in finalize_response
    assert isinstance(response, HttpResponseBase), (
           ~~~~~~~~~~^^^^^^^^^^^^^^^^^^^^^^^^^^^^
AssertionError: Expected a `Response`, `HttpResponse` or `StreamingHttpResponse` to be returned from the view, but received a `<class 'NoneType'>`
[2025-08-27 14:38:05,979] CRITICAL django.request: Platform is running at risk
[2025-08-27 14:38:05,979] INFO django.request: MyView GET called by user AnonymousUser
[2025-08-27 14:38:05,995] WARNING django.request: Bad Request: /
[2025-08-28 06:34:06,180] CRITICAL django.request: Platform is running at risk
[2025-08-28 06:34:06,181] INFO django.request: MyView GET called by user AnonymousUser
[2025-08-28 06:34:06,192] WARNING django.request: Bad Request: /
[2025-08-28 06:34:06,286] WARNING django.request: Not Found: /favicon.ico
[2025-08-28 06:38:57,933] WARNING django.request: Not Found: /api/v1/
[2025-08-28 06:39:11,273] WARNING django.request: Method Not Allowed: /api/v1/auth/jwt/register/
[2025-08-28 06:43:25,079] WARNING django.request: Method Not Allowed: /api/v1/auth/jwt/register/
[2025-08-28 06:43:26,618] WARNING django.request: Method Not Allowed: /api/v1/auth/jwt/register/
[2025-08-28 06:43:45,578] WARNING django.request: Bad Request: /api/v1/auth/jwt/register/
[2025-08-28 06:45:31,548] WARNING django.request: Bad Request: /api/v1/auth/jwt/register/
[2025-08-28 06:46:15,909] WARNING django.request: Method Not Allowed: /api/v1/auth/jwt/register/
[2025-08-28 13:35:46,012] WARNING django.request: Bad Request: /
[2025-08-28 13:35:46,068] WARNING django.request: Bad Request: /favicon.ico
[2025-08-28 13:36:08,845] CRITICAL django.request: Platform is running at risk
[2025-08-28 13:36:08,845] INFO django.request: MyView GET called by user AnonymousUser
[2025-08-28 13:36:08,863] WARNING django.request: Bad Request: /
[2025-08-28 13:36:08,967] WARNING django.request: Not Found: /favicon.ico
[2025-08-28 13:54:58,813] WARNING django.request: Not Found: /accounts/login/
[2025-08-30 19:11:48,170] CRITICAL django.request: Platform is running at risk
[2025-08-30 19:11:48,170] INFO django.request: MyView GET called by user AnonymousUser
[2025-08-30 19:11:48,179] WARNING django.request: Bad Request: /
[2025-08-30 19:11:48,247] WARNING django.request: Not Found: /favicon.ico
[2025-08-30 19:11:55,346] WARNING django.request: Not Found: /auth
[2025-08-30 19:12:04,341] WARNING django.request: Not Found: /api/v1
[2025-08-30 19:12:13,297] WARNING django.request: Not Found: /api/v1/
[2025-08-30 19:30:14,144] WARNING django.request: Not Found: /api/v1/
[2025-08-30 19:30:31,334] WARNING django.request: Not Found: /accounts/login/
[2025-08-31 06:25:02,512] CRITICAL django.request: Platform is running at risk
[2025-08-31 06:25:02,512] INFO django.request: MyView GET called by user AnonymousUser
[2025-08-31 06:25:02,524] WARNING django.request: Bad Request: /
[2025-08-31 06:25:02,597] WARNING django.request: Not Found: /favicon.ico
[2025-08-31 06:25:52,020] CRITICAL django.request: Platform is running at risk
[2025-08-31 06:25:52,020] INFO django.request: MyView GET called by user AnonymousUser
[2025-08-31 06:25:52,036] WARNING django.request: Bad Request: /
[2025-08-31 06:28:03,279] WARNING django.request: Bad Request: /api/v1/auth/jwt/reset/
[2025-08-31 06:28:29,600] WARNING django.request: Bad Request: /api/v1/auth/jwt/login/
[2025-08-31 06:29:38,082] WARNING django.request: Bad Request: /api/v1/auth/jwt/login/
[2025-08-31 06:36:14,047] WARNING django.request: Unauthorized: /api/v1/auth/jwt/token/verify/
[2025-08-31 06:41:24,272] WARNING django.request: Bad Request: /api/v1/auth/jwt/logout/
[2025-08-31 06:43:56,889] WARNING django.request: Bad Request: /api/v1/auth/jwt/register/
[2025-08-31 06:49:29,249] WARNING django.request: Not Found: /accounts/login/
[2025-08-31 06:56:02,276] WARNING django.request: Bad Request: /api/v1/auth/jwt/register/
[2025-08-31 08:05:15,641] ERROR django.request: Internal Server Error: /
Traceback (most recent call last):
  File "/Users/modarwish/Documents/Learn/backend/temp/demoapp/path/to/venv/lib/python3.13/site-packages/django/core/handlers/exception.py", line 55, in inner
    response = get_response(request)
  File "/Users/modarwish/Documents/Learn/backend/temp/demoapp/path/to/venv/lib/python3.13/site-packages/django/core/handlers/base.py", line 197, in _get_response
    response = wrapped_callback(request, *callback_args, **callback_kwargs)
  File "/Users/modarwish/Documents/Learn/backend/temp/demoapp/path/to/venv/lib/python3.13/site-packages/django/views/decorators/csrf.py", line 56, in wrapper_view
    return view_func(*args, **kwargs)
  File "/Users/modarwish/Documents/Learn/backend/temp/demoapp/path/to/venv/lib/python3.13/site-packages/django/views/generic/base.py", line 104, in view
    return self.dispatch(request, *args, **kwargs)
           ~~~~~~~~~~~~~^^^^^^^^^^^^^^^^^^^^^^^^^^
  File "/Users/modarwish/Documents/Learn/backend/temp/demoapp/path/to/venv/lib/python3.13/site-packages/rest_framework/views.py", line 515, in dispatch
    response = self.handle_exception(exc)
  File "/Users/modarwish/Documents/Learn/backend/temp/demoapp/path/to/venv/lib/python3.13/site-packages/rest_framework/views.py", line 475, in handle_exception
    self.raise_uncaught_exception(exc)
    ~~~~~~~~~~~~~~~~~~~~~~~~~~~~~^^^^^
  File "/Users/modarwish/Documents/Learn/backend/temp/demoapp/path/to/venv/lib/python3.13/site-packages/rest_framework/views.py", line 486, in raise_uncaught_exception
    raise exc
  File "/Users/modarwish/Documents/Learn/backend/temp/demoapp/path/to/venv/lib/python3.13/site-packages/rest_framework/views.py", line 512, in dispatch
    response = handler(request, *args, **kwargs)
  File "/Users/modarwish/Documents/Learn/backend/temp/demoapp/path/to/venv/lib/python3.13/site-packages/drf_yasg/views.py", line 112, in get
    schema = generator.get_schema(request, self.public)
  File "/Users/modarwish/Documents/Learn/backend/temp/demoapp/path/to/venv/lib/python3.13/site-packages/drf_yasg/generators.py", line 276, in get_schema
    paths, prefix = self.get_paths(endpoints, components, request, public)
                    ~~~~~~~~~~~~~~^^^^^^^^^^^^^^^^^^^^^^^^^^^^^^^^^^^^^^^^
  File "/Users/modarwish/Documents/Learn/backend/temp/demoapp/path/to/venv/lib/python3.13/site-packages/drf_yasg/generators.py", line 482, in get_paths
    operation = self.get_operation(view, path, prefix, method, components, request)
  File "/Users/modarwish/Documents/Learn/backend/temp/demoapp/path/to/venv/lib/python3.13/site-packages/drf_yasg/generators.py", line 524, in get_operation
    operation = view_inspector.get_operation(operation_keys)
  File "/Users/modarwish/Documents/Learn/backend/temp/demoapp/path/to/venv/lib/python3.13/site-packages/drf_yasg/inspectors/view.py", line 36, in get_operation
    parameters = self.add_manual_parameters(parameters)
  File "/Users/modarwish/Documents/Learn/backend/temp/demoapp/path/to/venv/lib/python3.13/site-packages/drf_yasg/inspectors/view.py", line 161, in add_manual_parameters
    if any(param.in_ == openapi.IN_BODY for param in manual_parameters):  # pragma: no cover
       ~~~^^^^^^^^^^^^^^^^^^^^^^^^^^^^^^^^^^^^^^^^^^^^^^^^^^^^^^^^^^^^^
  File "/Users/modarwish/Documents/Learn/backend/temp/demoapp/path/to/venv/lib/python3.13/site-packages/drf_yasg/inspectors/view.py", line 161, in <genexpr>
    if any(param.in_ == openapi.IN_BODY for param in manual_parameters):  # pragma: no cover
           ^^^^^^^^^
AttributeError: 'str' object has no attribute 'in_'
[2025-08-31 08:05:17,923] ERROR django.request: Internal Server Error: /
Traceback (most recent call last):
  File "/Users/modarwish/Documents/Learn/backend/temp/demoapp/path/to/venv/lib/python3.13/site-packages/django/core/handlers/exception.py", line 55, in inner
    response = get_response(request)
  File "/Users/modarwish/Documents/Learn/backend/temp/demoapp/path/to/venv/lib/python3.13/site-packages/django/core/handlers/base.py", line 197, in _get_response
    response = wrapped_callback(request, *callback_args, **callback_kwargs)
  File "/Users/modarwish/Documents/Learn/backend/temp/demoapp/path/to/venv/lib/python3.13/site-packages/django/views/decorators/csrf.py", line 56, in wrapper_view
    return view_func(*args, **kwargs)
  File "/Users/modarwish/Documents/Learn/backend/temp/demoapp/path/to/venv/lib/python3.13/site-packages/django/views/generic/base.py", line 104, in view
    return self.dispatch(request, *args, **kwargs)
           ~~~~~~~~~~~~~^^^^^^^^^^^^^^^^^^^^^^^^^^
  File "/Users/modarwish/Documents/Learn/backend/temp/demoapp/path/to/venv/lib/python3.13/site-packages/rest_framework/views.py", line 515, in dispatch
    response = self.handle_exception(exc)
  File "/Users/modarwish/Documents/Learn/backend/temp/demoapp/path/to/venv/lib/python3.13/site-packages/rest_framework/views.py", line 475, in handle_exception
    self.raise_uncaught_exception(exc)
    ~~~~~~~~~~~~~~~~~~~~~~~~~~~~~^^^^^
  File "/Users/modarwish/Documents/Learn/backend/temp/demoapp/path/to/venv/lib/python3.13/site-packages/rest_framework/views.py", line 486, in raise_uncaught_exception
    raise exc
  File "/Users/modarwish/Documents/Learn/backend/temp/demoapp/path/to/venv/lib/python3.13/site-packages/rest_framework/views.py", line 512, in dispatch
    response = handler(request, *args, **kwargs)
  File "/Users/modarwish/Documents/Learn/backend/temp/demoapp/path/to/venv/lib/python3.13/site-packages/drf_yasg/views.py", line 112, in get
    schema = generator.get_schema(request, self.public)
  File "/Users/modarwish/Documents/Learn/backend/temp/demoapp/path/to/venv/lib/python3.13/site-packages/drf_yasg/generators.py", line 276, in get_schema
    paths, prefix = self.get_paths(endpoints, components, request, public)
                    ~~~~~~~~~~~~~~^^^^^^^^^^^^^^^^^^^^^^^^^^^^^^^^^^^^^^^^
  File "/Users/modarwish/Documents/Learn/backend/temp/demoapp/path/to/venv/lib/python3.13/site-packages/drf_yasg/generators.py", line 482, in get_paths
    operation = self.get_operation(view, path, prefix, method, components, request)
  File "/Users/modarwish/Documents/Learn/backend/temp/demoapp/path/to/venv/lib/python3.13/site-packages/drf_yasg/generators.py", line 524, in get_operation
    operation = view_inspector.get_operation(operation_keys)
  File "/Users/modarwish/Documents/Learn/backend/temp/demoapp/path/to/venv/lib/python3.13/site-packages/drf_yasg/inspectors/view.py", line 36, in get_operation
    parameters = self.add_manual_parameters(parameters)
  File "/Users/modarwish/Documents/Learn/backend/temp/demoapp/path/to/venv/lib/python3.13/site-packages/drf_yasg/inspectors/view.py", line 161, in add_manual_parameters
    if any(param.in_ == openapi.IN_BODY for param in manual_parameters):  # pragma: no cover
       ~~~^^^^^^^^^^^^^^^^^^^^^^^^^^^^^^^^^^^^^^^^^^^^^^^^^^^^^^^^^^^^^
  File "/Users/modarwish/Documents/Learn/backend/temp/demoapp/path/to/venv/lib/python3.13/site-packages/drf_yasg/inspectors/view.py", line 161, in <genexpr>
    if any(param.in_ == openapi.IN_BODY for param in manual_parameters):  # pragma: no cover
           ^^^^^^^^^
AttributeError: 'str' object has no attribute 'in_'
[2025-08-31 08:05:26,394] WARNING django.request: Not Found: /swagger/
[2025-08-31 08:05:30,555] ERROR django.request: Internal Server Error: /
Traceback (most recent call last):
  File "/Users/modarwish/Documents/Learn/backend/temp/demoapp/path/to/venv/lib/python3.13/site-packages/django/core/handlers/exception.py", line 55, in inner
    response = get_response(request)
  File "/Users/modarwish/Documents/Learn/backend/temp/demoapp/path/to/venv/lib/python3.13/site-packages/django/core/handlers/base.py", line 197, in _get_response
    response = wrapped_callback(request, *callback_args, **callback_kwargs)
  File "/Users/modarwish/Documents/Learn/backend/temp/demoapp/path/to/venv/lib/python3.13/site-packages/django/views/decorators/csrf.py", line 56, in wrapper_view
    return view_func(*args, **kwargs)
  File "/Users/modarwish/Documents/Learn/backend/temp/demoapp/path/to/venv/lib/python3.13/site-packages/django/views/generic/base.py", line 104, in view
    return self.dispatch(request, *args, **kwargs)
           ~~~~~~~~~~~~~^^^^^^^^^^^^^^^^^^^^^^^^^^
  File "/Users/modarwish/Documents/Learn/backend/temp/demoapp/path/to/venv/lib/python3.13/site-packages/rest_framework/views.py", line 515, in dispatch
    response = self.handle_exception(exc)
  File "/Users/modarwish/Documents/Learn/backend/temp/demoapp/path/to/venv/lib/python3.13/site-packages/rest_framework/views.py", line 475, in handle_exception
    self.raise_uncaught_exception(exc)
    ~~~~~~~~~~~~~~~~~~~~~~~~~~~~~^^^^^
  File "/Users/modarwish/Documents/Learn/backend/temp/demoapp/path/to/venv/lib/python3.13/site-packages/rest_framework/views.py", line 486, in raise_uncaught_exception
    raise exc
  File "/Users/modarwish/Documents/Learn/backend/temp/demoapp/path/to/venv/lib/python3.13/site-packages/rest_framework/views.py", line 512, in dispatch
    response = handler(request, *args, **kwargs)
  File "/Users/modarwish/Documents/Learn/backend/temp/demoapp/path/to/venv/lib/python3.13/site-packages/drf_yasg/views.py", line 112, in get
    schema = generator.get_schema(request, self.public)
  File "/Users/modarwish/Documents/Learn/backend/temp/demoapp/path/to/venv/lib/python3.13/site-packages/drf_yasg/generators.py", line 276, in get_schema
    paths, prefix = self.get_paths(endpoints, components, request, public)
                    ~~~~~~~~~~~~~~^^^^^^^^^^^^^^^^^^^^^^^^^^^^^^^^^^^^^^^^
  File "/Users/modarwish/Documents/Learn/backend/temp/demoapp/path/to/venv/lib/python3.13/site-packages/drf_yasg/generators.py", line 482, in get_paths
    operation = self.get_operation(view, path, prefix, method, components, request)
  File "/Users/modarwish/Documents/Learn/backend/temp/demoapp/path/to/venv/lib/python3.13/site-packages/drf_yasg/generators.py", line 524, in get_operation
    operation = view_inspector.get_operation(operation_keys)
  File "/Users/modarwish/Documents/Learn/backend/temp/demoapp/path/to/venv/lib/python3.13/site-packages/drf_yasg/inspectors/view.py", line 36, in get_operation
    parameters = self.add_manual_parameters(parameters)
  File "/Users/modarwish/Documents/Learn/backend/temp/demoapp/path/to/venv/lib/python3.13/site-packages/drf_yasg/inspectors/view.py", line 161, in add_manual_parameters
    if any(param.in_ == openapi.IN_BODY for param in manual_parameters):  # pragma: no cover
       ~~~^^^^^^^^^^^^^^^^^^^^^^^^^^^^^^^^^^^^^^^^^^^^^^^^^^^^^^^^^^^^^
  File "/Users/modarwish/Documents/Learn/backend/temp/demoapp/path/to/venv/lib/python3.13/site-packages/drf_yasg/inspectors/view.py", line 161, in <genexpr>
    if any(param.in_ == openapi.IN_BODY for param in manual_parameters):  # pragma: no cover
           ^^^^^^^^^
AttributeError: 'str' object has no attribute 'in_'
